File: NdTiGaO_multifield_He3Base._50K.dat
[Header]
TITLE,NdTiGaO_multifield_He3Base._50K.dat
BYAPP,HeatCapacity,3.9.3,1.7
INFO,6.856,MASS:Sample Mass (mg)
INFO,0.005,MASSERR:Sample Mass Error (mg)
INFO,,MOLWGHT:Formula Weight (g/mole)
INFO,,ATOMS:Atoms per Formula Unit
INFO,PPMS Heat Capacity Option 3.9.3 Build 101,APPNAME
DATATYPE,TIME,1
DATATYPE,COMMENT,2
STARTUPAXIS, X, 8, LINEAR, AUTO
STARTUPAXIS, Y1, 10, LINEAR, AUTO
[Data]
Time Stamp (Seconds),Comment (),System Status (Code),Puck Temp (Kelvin),System Temp (Kelvin),Field (Oersted),Pressure (Torr),Sample Temp (Kelvin),Temp Rise (Kelvin),Samp HC (µJ/K),Samp HC Err (µJ/K),Addenda HC (µJ/K),Addenda HC Err (µJ/K),Total HC (µJ/K),Total HC Err (µJ/K),Fit Deviation (ChiSquare),Time Const tau1 (seconds),Time Const tau2 (seconds),Sample Coupling (Percent),Debye Temp (Kelvin),Debye Temp Err (Kelvin),Cal Correction (Factor),Therm Resist (Ohms),Htr Resist (Ohms),Puck Resist (Ohms),Wire Cond (W/K),Meas Time (seconds),Temp Squared (K^2),Samp HC/Temp (µJ/K/K),Addenda Offset HC (µJ/K)
3762071346.49882,CALFILE: He3Puck895.cal - Addenda #1 measured on 3/15/2019 from 0.34839 to 50.713 K
3762071346.49944,,1857,50.025,50.025,-0.178470730781555,9.89999989542412E-6,50.618027,1.001998,602.2885,3.068,428.44369,0.4119,1030.7322,3.068,0.0886739,83.693563,0.32829877,98.393117,0,0,1,,,,1.2384E-5,145.7648,2562.1846,11.898696,0
3762077823.11257,,1857,44.9022,44.9022,0.107082441449165,9.89999989542412E-6,45.46559,0.92863385,516.14789,2.213,347.74173,0.2894,863.88961,2.213,0.10706173,74.027424,0.24374182,98.636202,0,0,1,,,,1.1728E-5,141.3006,2067.1199,11.352495,0
3762083340.82938,,1857,40.4114,40.4114,0.0594902411103249,9.89999989542412E-6,40.976038,0.86089579,434.18801,0.9156,285.57531,0.2349,719.76333,0.9156,0.11697338,63.152809,0.070074284,99.536978,0,0,1,,,,1.1416E-5,136.0244,1679.0357,10.596144,0
3762091530.23558,,1857,32.6155,32.6155,-0.178470730781555,9.89999989542412E-6,33.07401,0.6673186,300.66711,0.6482,193.654,0.1659,494.32111,0.6267,0.19976601,49.303497,0,100,0,0,1,,,,1.0026E-5,110.2587,1093.8901,9.0907363,0
3762095597.28662,,1857,29.2588,29.2588,-0.011898048222065,9.89999989542412E-6,29.646435,0.60816511,248.08239,1.059,158.78697,0.1495,406.86936,1.059,0.098154629,46.8221,0.13570139,98.785776,0,0,1,,,,8.7295E-6,91.41055,878.91113,8.3680345,0
3762098564.46649,,1857,26.2547,26.2547,-0.130878537893295,9.89999989542412E-6,26.6091,0.5303687,199.96891,0.4591,129.6014,0.1131,329.57031,0.4591,0.34466329,40.152644,0.078887939,99.178348,0,0,1,,,,8.233E-6,76.41563,708.04419,7.5150575,0
3762102271.65272,,1857,21.2367,21.2367,-0.19036877155304,9.89999989542412E-6,21.561135,0.45314708,122.26141,0.3527,86.250032,0.07712,208.51145,0.3442,1.6183114,29.288395,0,100,0,0,1,,,,7.1193E-6,68.96366,464.88252,5.6704536,0
3762104327.41051,,1857,19.0454,19.0454,-0.237960964441299,9.89999989542412E-6,19.325626,0.37754315,93.3792,0.2719,69.629241,0.08681,163.00844,0.2577,0.22469593,25.067704,0,100,0,0,1,,,,6.5027E-6,51.15505,373.47982,4.8318849,0
3762105543.38014,,1857,17.1027,17.1027,-0.130878537893295,9.89999989542412E-6,17.34941,0.3594127,69.655192,0.2265,55.756615,0.0808,125.41181,0.2265,0.32903165,22.549573,0.04126409,99.261015,0,0,1,,,,5.5744E-6,46.24543,301.00204,4.0148449,0
3762107021.84,,1857,13.7677,13.7677,-0.011898048222065,9.89999989542412E-6,13.986171,0.30339236,35.860178,0.1481,35.064773,0.04913,70.924952,0.1397,0.29659426,15.494827,0,100,0,0,1,,,,4.5773E-6,38.04281,195.61298,2.5639739,0
3762107891.21871,,1857,12.3792,12.3792,-0.0832863375544548,9.89999989542412E-6,12.561141,0.25146753,24.832416,0.06864,27.453125,0.03839,52.285541,0.06864,3.1376834,13.286095,0.023713476,99.287063,0,0,1,,,,3.9417E-6,26.00053,157.78225,1.9769237,0
3762108645.2464,,1857,11.1247,11.1247,-0.0237960964441299,9.89999989542412E-6,11.289984,0.22731054,17.061752,0.05093,21.477374,0.03206,38.539126,0.05093,2.2156401,11.122423,0.016460032,99.402344,0,0,1,,,,3.4691E-6,22.04469,127.46373,1.5112291,0
3762109943.2715,,1857,8.98106,8.98106,-0.0237960964441299,9.89999989542412E-6,9.1189822,0.19557023,7.8685745,0.07616,12.923312,0.02525,20.791887,0.07185,0.68113243,7.8661466,0,100,0,0,1,,,,2.6432E-6,18.54945,83.155837,0.86287858,0
3762110775.42113,,1857,8.06901,8.06901,-0.0475921928882599,9.89999989542412E-6,8.1896408,0.16515793,5.2145765,0.03432,9.8728918,0.02684,15.087468,0.03432,1.1536312,6.5960015,0.019070362,98.73396,0,0,1,,,,2.2909E-6,13.21748,67.070217,0.63672835,0
3762111559.02922,,1857,7.24838,7.24838,-0.0237960964441299,9.89999989542412E-6,7.355149,0.14724567,3.5574116,0.02331,7.4563804,0.01867,11.013792,0.02331,1.6599351,5.5601769,0.019123766,98.446432,0,0,1,,,,1.9841E-6,11.07552,54.098217,0.48366275,0
3762112813.6417,,1857,5.84161,5.84161,-0.011898048222065,9.89999989542412E-6,5.933417,0.12584052,1.8945653,0.02277,4.1905557,0.01079,6.085121,0.02005,0.82409202,4.0642717,0,100,0,0,1,,,,1.4972E-6,9.437874,35.205437,0.31930426,0
3762113511.16861,,1857,5.24982,5.24982,-0.0237960964441299,9.89999989542412E-6,5.3278302,0.1068395,1.47479,0.00981,3.0925495,0.007937,4.5673395,0.00981,1.265137,3.5204913,0.0083668045,98.922249,0,0,1,,,,1.2988E-6,7.04626,28.385775,0.27680874,0
3762114186.48168,,1857,4.71708,4.71708,-0.0475921928882599,9.89999989542412E-6,4.7884464,0.096543868,1.2452385,0.007729,2.268133,0.006106,3.5133715,0.007729,1.3170449,3.1050218,0.0016779587,99.764237,0,0,1,,,,1.1318E-6,6.216088,22.929219,0.26005062,0
3762115353.31964,,1857,3.80212,3.80212,-0.011898048222065,9.89999989542412E-6,3.8622934,0.080699266,1.0668897,0.00688,1.1944534,0.003376,2.2613431,0.00688,1.1974624,2.6531923,0.0032413262,99.5111,0,0,1,,,,8.5324E-7,5.609021,14.91731,0.27623217,0
3762115763.24509,,1857,3.42013,3.42013,-0.0356941446661949,9.89999989542412E-6,3.4728811,0.070528527,1.0593426,0.006989,0.86877017,0.004781,1.9281128,0.006989,1.3332672,2.5676699,0.0010436373,99.835921,0,0,1,,,,7.5129E-7,5.154186,12.060903,0.30503279,0
3762116082.94591,,1857,3.07202,3.07202,-0.0475921928882599,9.89999989542412E-6,3.1202589,0.063860816,1.1079091,0.006086,0.61486192,0.003286,1.7227711,0.006086,1.1640509,2.6335679,0.0015369667,99.745842,0,0,1,,,,6.5485E-7,5.292062,9.7360157,0.35506962,0
3762116570.80675,,1857,2.47846,2.47846,-0.0237960964441299,9.89999989542412E-6,2.5153232,0.047588444,1.2778846,0.004937,0.32019424,0.001495,1.5980789,0.004937,0.78932109,3.1582593,0.00081140815,99.839573,0,0,1,,,,5.0652E-7,5.643252,6.3268507,0.50803993,0
3762116936.88829,,1857,2.22672,2.22672,-0.11898048222065,9.89999989542412E-6,2.2607932,0.046332503,1.4073804,0.007101,0.23125513,0.001432,1.6386356,0.007101,1.1350462,3.6884878,0.0015064522,99.662504,0,0,1,,,,4.4537E-7,7.392839,5.1111857,0.62251623,0
3762117315.2378,,1857,2.00003,2.00003,-0.130878537893295,9.89999989542412E-6,2.0297325,0.042305308,1.5493307,0.006524,0.16758212,0.001441,1.7169128,0.006524,1.1680058,4.4672679,0.0014089714,99.641104,0,0,1,,,,3.8546E-7,8.790758,4.1198141,0.76331767,0
3762117776.52122,,1857,1.61376,1.61376,-0.0475921928882599,9.89999989542412E-6,1.6363593,0.029656946,1.9746358,0.006367,0.094286183,0.0005727,2.068922,0.006367,0.65510725,6.7395969,0.00046021838,99.842803,0,0,1,,,,3.0742E-7,10.79683,2.6776717,1.2067251,0
3762118170.76505,,1857,1.44954,1.44954,-0.011898048222065,9.89999989542412E-6,1.471415,0.03092358,2.2558557,0.004939,0.072490163,0.0004072,2.3283458,0.004939,0.69219171,8.5140985,0.00037855143,99.852411,0,0,1,,,,2.7385E-7,16.95183,2.1650621,1.5331199,0
3762118649.09134,,1857,1.30202,1.30202,-0.0356941446661949,9.89999989542412E-6,1.3221171,0.028248376,2.6117082,0.005692,0.056638774,0.0002363,2.668347,0.005692,1.0188016,11.135817,0.00095153453,99.587147,0,0,1,,,,2.4057E-7,22.05669,1.7479937,1.9753985,0
3762119306.1948,,1857,1.05049,1.05049,0.0475921928882599,9.89999989542412E-6,1.064021,0.019249091,3.5343309,0.008157,0.036036439,0.0003512,3.5703673,0.008157,0.65339445,18.482508,0.00042985072,99.766704,0,0,1,,,,1.9362E-7,28.58605,1.1321408,3.3216739,0
3762120062.32602,,1857,0.943667,0.943667,0.0713882893323898,9.89999989542412E-6,0.95740898,0.02072019,4.1582241,0.006864,0.029429441,0.0002335,4.1876536,0.006864,0.34721192,24.444548,0.00029301146,99.82794,0,0,1,,,,1.716E-7,48.316,0.91663195,4.3432057,0
3762121112.66434,,1857,0.847714,0.847714,0,9.89999989542412E-6,0.85923222,0.018942754,4.9069048,0.01016,0.024328551,0.0002831,4.9312334,0.01016,0.65684638,32.926198,0.00054616832,99.660986,0,0,1,,,,1.5027E-7,64.81568,0.73828001,5.7108017,0
3762122771.57949,,1857,0.683984,0.683984,-0.0713882893323898,9.89999989542412E-6,0.69127543,0.012908223,7.1626191,0.01402,0.017417362,0.0001675,7.1800365,0.01402,0.55071336,58.632682,0.00042961783,99.696296,0,0,1,,,,1.2283E-7,86.00042,0.47786172,10.361455,0
3762124943.18803,,1857,0.614408,0.614408,-0.0832863375544548,9.89999989542412E-6,0.62145907,0.013558802,8.6661542,0.01475,0.015158463,0.0001793,8.6813127,0.01475,0.51613576,79.356994,0.00016368181,99.881528,0,0,1,,,,1.0952E-7,157.5294,0.38621137,13.944851,0
3762128113.82188,,1857,0.551915,0.551915,0,9.89999989542412E-6,0.55674035,0.012370221,10.240625,0.01661,0.013255048,0.0001828,10.25388,0.01661,0.893453,107.79718,0.00084781023,99.387062,0,0,1,,,,9.5707E-8,211.9396,0.30995981,18.393897,0
3762133163.91117,,1857,0.445287,0.445287,-0.0832863375544548,9.89999989542412E-6,0.44843091,0.0094508952,14.158309,0.02531,0.010784308,7.584E-5,14.169094,0.02531,0.29389863,180.48221,0.00066557982,99.51274,0,0,1,,,,7.8891E-8,280.4704,0.20109028,31.573,0
3762139942.61099,,1857,0.400086,0.400086,-0.154674634337425,9.89999989542412E-6,0.40177861,0.0087141747,16.046893,0.02642,0.009694337,8.825E-5,16.056587,0.02642,0.37785768,236.05645,0.0011897185,99.157654,0,0,1,,,,6.8597E-8,454.6716,0.16142605,39.93964,0
3762147296.388,,1857,50.0522,50.0522,4999.9287109375,9.89999989542412E-6,50.730065,1.0423556,599.27875,0.8886,430.00634,0.4149,1029.2851,0.8886,0.46218109,77.356007,0.081776998,99.56599,0,0,1,,,,1.3326E-5,161.4747,2573.5395,11.813089,0
3762156877.22474,,1857,40.1979,40.1979,5000.01220703125,9.89999989542412E-6,40.756801,0.87972769,435.50598,0.8185,282.73458,0.2327,718.24056,0.8185,0.63154477,63.511275,0.10722342,99.294007,0,0,1,,,,1.1338E-5,141.9432,1661.1168,10.68548,0
3762161839.02186,,1857,36.2684,36.2684,4999.845703125,9.89999989542412E-6,36.724244,0.76239766,368.44666,2.365,233.80336,0.1879,602.25002,2.365,0.073564327,61.437848,0.25841062,98.236738,0,0,1,,,,9.8687E-6,117.2163,1348.6701,10.032791,0
3762167095.86737,,1857,32.5412,32.5412,4999.90478515625,9.89999989542412E-6,32.975492,0.65158807,301.29676,0.4635,192.63595,0.1657,493.93271,0.4635,1.6890299,50.60139,0.072473334,99.398887,0,0,1,,,,9.7832E-6,97.65284,1087.3831,9.1369906,0
3762172209.41726,,1857,26.3619,26.3619,4999.9287109375,9.89999989542412E-6,26.758188,0.54316007,196.99049,0.8545,130.93965,0.1145,327.93014,0.8468,4.381227,37.351943,0,100,0,0,1,,,,8.7795E-6,87.42094,716.00063,7.361877,0
3762175152.35313,,1857,23.574,23.574,4999.95263671875,9.89999989542412E-6,23.906126,0.46733968,157.03491,0.3387,105.56673,0.09279,262.60164,0.3258,0.10631208,33.402541,0,100,0,0,1,,,,7.8617E-6,66.82911,571.50284,6.5688149,0
3762177418.78251,,1857,21.1831,21.1831,4999.86962890625,9.89999989542412E-6,21.480916,0.42858891,122.35738,0.1871,85.622029,0.07691,207.97941,0.1871,1.7902463,29.680687,0.023692456,99.670753,0,0,1,,,,7.0152E-6,57.99525,461.42977,5.6960968,0
3762179782.99458,,1857,17.0285,17.0285,4999.9169921875,9.89999989542412E-6,17.274524,0.37598397,69.439048,0.1687,55.228026,0.07983,124.66707,0.1687,2.656724,22.233128,0.029909646,99.455928,0,0,1,,,,5.6168E-6,50.4886,298.40919,4.0197372,0
3762180891.69271,,1857,15.337,15.337,4999.90478515625,9.89999989542412E-6,15.546316,0.31242286,50.633482,0.1637,44.05782,0.05965,94.691303,0.1637,0.50485602,19.245867,0.048869315,98.98381,0,0,1,,,,4.9346E-6,37.10762,241.68794,3.2569441,0
3762181856.84805,,1857,13.7917,13.7917,4999.9404296875,9.89999989542412E-6,13.984026,0.27759869,36.320293,0.1647,35.064372,0.04912,71.384666,0.1572,1.3816803,15.870059,0,100,0,0,1,,,,4.4981E-6,31.90159,195.55298,2.5972702,0
3762183051.91069,,1857,11.1224,11.1224,4999.89306640625,9.89999989542412E-6,11.295457,0.24413425,17.216578,0.09188,21.497068,0.03209,38.713646,0.08609,0.37772282,10.93076,0,100,0,0,1,,,,3.5417E-6,26.73354,127.58735,1.5242038,0
3762183722.32218,,1857,9.99143,9.99143,4999.88134765625,9.89999989542412E-6,10.13558,0.20180983,11.866299,0.03639,16.657819,0.02232,28.524118,0.03639,2.1529465,9.3115238,0.0070418158,99.689349,0,0,1,,,,3.065E-6,18.3728,102.72998,1.1707568,0
3762184675.70711,,1857,8.98602,8.98602,4999.90478515625,9.89999989542412E-6,9.1104931,0.17955262,8.2175688,0.08225,12.899575,0.02531,21.117143,0.07826,1.2797973,7.8905437,0,100,0,0,1,,,,2.6763E-6,15.86196,83.001085,0.90198946,0
3762186022.79857,,1857,7.24248,7.24248,4999.90478515625,9.89999989542412E-6,7.3501423,0.15803775,4.2493056,0.02453,7.4403751,0.01862,11.689681,0.02453,0.80430416,5.9003871,0.0037367165,99.726833,0,0,1,,,,1.9819E-6,13.46798,54.024591,0.57812562,0
3762186779.66535,,1857,6.50836,6.50836,4999.89306640625,9.89999989542412E-6,6.6020786,0.13008933,3.2978967,0.03524,5.6261085,0.01438,8.9240052,0.03218,1.4391247,5.151143,0,100,0,0,1,,,,1.7324E-6,10.41098,43.587441,0.499524,0
3762187506.80173,,1857,5.84718,5.84718,4999.82177734375,9.89999989542412E-6,5.9308555,0.11692318,2.8105985,0.03078,4.1866888,0.01078,6.9972873,0.02883,1.8256721,4.6575737,0,100,0,0,1,,,,1.5023E-6,9.363428,35.175047,0.47389429,0
3762188706.27874,,1857,4.71284,4.71284,4999.95263671875,9.89999989542412E-6,4.7801176,0.094695748,2.6433548,0.01618,2.2584241,0.006083,4.9017789,0.015,0.92502667,4.3613105,0,100,0,0,1,,,,1.1239E-6,8.752953,22.849525,0.55298948,0
3762189405.72195,,1857,4.2361,4.2361,4999.9287109375,9.89999989542412E-6,4.2990771,0.088170822,2.8135058,0.008488,1.6423922,0.003785,4.455898,0.008488,0.83931407,4.5777825,0.0048750836,99.542835,0,0,1,,,,9.7516E-7,9.246936,18.482064,0.65444415,0
3762190116.0009,,1857,3.80661,3.80661,4999.857421875,9.89999989542412E-6,3.8627868,0.078983322,3.1420131,0.01448,1.1944977,0.003375,4.3365109,0.01448,1.4971799,5.1101383,0.0058499339,99.426231,0,0,1,,,,8.5118E-7,10.22905,14.921122,0.81340579,0
3762190752.57846,,1857,3.07226,3.07226,4999.82177734375,9.89999989542412E-6,3.1135879,0.055676241,4.2134755,0.01521,0.6109036,0.003256,4.8243791,0.01521,1.2040258,7.4481703,0.0012435258,99.848915,0,0,1,,,,6.4847E-7,11.98164,9.6944295,1.3532541,0
3762191206.10363,,1857,2.75944,2.75944,4999.857421875,9.89999989542412E-6,2.8009888,0.057831254,4.9446927,0.01126,0.4403065,0.002297,5.3849991,0.01126,1.0480338,9.4241113,0.001968389,99.721272,0,0,1,,,,5.7275E-7,18.98055,7.8455384,1.7653382,0
3762191738.22428,,1857,2.47878,2.47878,4999.857421875,9.89999989542412E-6,2.5162031,0.051571071,5.857612,0.01167,0.3203941,0.001496,6.1780061,0.01167,0.52714813,12.229562,0.0015096709,99.748443,0,0,1,,,,5.0632E-7,24.51668,6.3312781,2.3279567,0
3762192588.09941,,1857,1.99993,1.99993,4999.857421875,9.89999989542412E-6,2.0254872,0.034597127,8.2468312,0.02297,0.16656895,0.001431,8.4134002,0.02297,0.95558811,21.686603,0.0011019046,99.737538,0,0,1,,,,3.8893E-7,32.20826,4.1025982,4.0715297,0
3762193466.10624,,1857,1.79647,1.79647,4999.845703125,9.89999989542412E-6,1.823815,0.038401078,9.6854351,0.01599,0.12535321,0.0008805,9.8107883,0.01599,0.62075322,28.458706,0.00097762601,99.726953,0,0,1,,,,3.4566E-7,57.10807,3.3263011,5.310536,0
3762194635.72957,,1857,1.61371,1.61371,4999.83349609375,9.89999989542412E-6,1.637178,0.034300975,11.589915,0.01591,0.094367773,0.0005733,11.684282,0.01591,0.63915923,37.709615,0.00063746269,99.788557,0,0,1,,,,3.1049E-7,75.88068,2.6803517,7.0792025,0
3762196443.90611,,1857,1.30208,1.30208,4999.82177734375,9.89999989542412E-6,1.3203333,0.024339248,16.215902,0.0202,0.056484291,0.0002353,16.272386,0.0202,0.21671807,65.726338,0.00039635895,99.825365,0,0,1,,,,2.4801E-7,100.1253,1.7432801,12.281673,0
3762198851.3448,,1857,1.16957,1.16957,4999.82177734375,9.89999989542412E-6,1.1872456,0.024864449,19.076126,0.07762,0.04497094,0.0003283,19.121097,0.07762,0.012097585,85.378108,0.00033522243,99.832385,0,0,1,,,,2.2433E-7,173.5315,1.409552,16.067549,0
3762202125.04462,,1857,1.05059,1.05059,4999.9287109375,9.89999989542412E-6,1.0664239,0.022597177,22.194306,0.02206,0.036188483,0.0003541,22.230495,0.02206,0.24844092,113.27893,0.00051575047,99.719075,0,0,1,,,,1.968E-7,226.3376,1.13726,20.811898,0
3762207249.83174,,1857,0.847713,0.847713,4999.96435546875,9.89999989542412E-6,0.86085163,0.018288792,29.223309,0.03148,0.024423533,0.0002814,29.247733,0.03148,0.16265286,189.27425,0.00048756933,99.690305,0,0,1,,,,1.55E-7,293.3939,0.74106552,33.946976,0
3762213838.21338,,1857,0.7615,0.7615,4999.98828125,9.89999989542412E-6,0.77312433,0.016617697,33.069646,0.03747,0.020414367,0.0003085,33.09006,0.03747,0.24321383,237.97762,0.00052550524,99.640557,0,0,1,,,,1.3955E-7,470.717,0.59772122,42.774033,0
3762222547.59695,,1857,0.683931,0.683931,4999.857421875,9.89999989542412E-6,0.69452547,0.014987405,36.846814,0.03808,0.0175204,0.0001723,36.864334,0.03808,0.14944718,296.74323,0.0005404775,99.615109,0,0,1,,,,1.2471E-7,593.3523,0.48236563,53.053222,0
3762236025.99086,,1857,0.551903,0.551903,4999.845703125,9.89999989542412E-6,0.56053744,0.012998474,43.945608,0.03093,0.013365967,0.000188,43.958974,0.03093,0.17157419,439.15264,0.00054606683,99.589234,0,0,1,,,,1.0051E-7,732.7643,0.31420222,78.399059,0
3762251598.86287,,1857,0.495831,0.495831,4999.9287109375,9.89999989542412E-6,0.50314224,0.011088647,46.951842,0.03563,0.01193919,0.0001042,46.963781,0.03563,0.10431925,535.05511,0.00065397316,99.516761,0,0,1,,,,8.82E-8,1000,0.25315212,93.317233,0
3762934627.67562,,1857,49.9993,49.9993,9999.7626953125,9.89999989542412E-6,50.584024,0.99882297,600.25613,0.8139,427.59413,0.4103,1027.8503,0.8139,0.35356194,76.077768,0.080050814,99.567482,0,0,1,,,,1.3531E-5,152.0207,2558.7435,11.866516,0
3762946567.52652,,1857,44.8781,44.8781,9999.7265625,9.89999989542412E-6,45.36741,0.91000085,517.53399,1.645,346.28861,0.2878,863.82261,1.645,0.18941756,73.180655,0.22991018,98.696663,0,0,1,,,,1.186E-5,137.9159,2058.2019,11.407616,0
3762965190.08425,,1857,36.1121,36.1121,9999.880859375,9.89999989542412E-6,36.551905,0.79904507,368.67295,0.7853,231.68915,0.1859,600.3621,0.7853,18.662809,57.578552,0.13322609,99.025952,0,0,1,,,,1.0466E-5,131.2011,1336.0418,10.086285,0
3762973508.92907,,1857,32.6079,32.6079,9999.9404296875,9.89999989542412E-6,32.941786,0.68642496,307.34735,2.495,192.38947,0.1657,499.73682,2.495,0.070282676,56.599655,0.30714459,97.7204,0,0,1,,,,8.9077E-6,104.8474,1085.1612,9.3300149,0
3762979274.05501,,1857,29.3202,29.3202,9999.8701171875,9.89999989542412E-6,29.688329,0.62874864,248.20031,0.4692,159.1127,0.1499,407.31301,0.4692,0.17806942,44.116559,0.025350727,99.758749,0,0,1,,,,9.241E-6,99.59045,881.39686,8.3601981,0
3762985930.1753,,1857,23.5321,23.5321,9999.9052734375,9.89999989542412E-6,23.826825,0.52254516,159.00752,0.2904,104.82697,0.09217,263.83449,0.2904,0.72240395,34.374994,0.03361863,99.592031,0,0,1,,,,7.6866E-6,80.06774,567.71759,6.6734666,0
3762988660.16155,,1857,21.1839,21.1839,9999.9169921875,9.89999989542412E-6,21.421169,0.43192044,123.65503,0.3694,85.174804,0.07679,208.82984,0.3694,0.2295303,30.859793,0.076659743,98.974543,0,0,1,,,,6.7917E-6,59.1218,458.8665,5.7725622,0
3762990807.33573,,1857,19.0236,19.0236,9999.9765625,9.89999989542412E-6,19.24326,0.37922139,94.39256,0.1835,69.027878,0.08734,163.42044,0.1835,0.94905835,25.69508,0.026971949,99.570371,0,0,1,,,,6.3692E-6,50.07968,370.30304,4.9052272,0
3762992994.88115,,1857,15.2964,15.2964,9999.9404296875,9.89999989542412E-6,15.477162,0.33507366,51.427324,0.132,43.62406,0.05909,95.051384,0.132,1.8236248,18.845607,0.025531344,99.455645,0,0,1,,,,5.0518E-6,43.14262,239.54255,3.3227877,0
3762994016.58722,,1857,13.7735,13.7735,9999.9169921875,9.89999989542412E-6,13.921918,0.2776888,36.930601,0.1198,34.714154,0.04864,71.644755,0.1198,0.59051544,16.278879,0.039208691,99.039972,0,0,1,,,,4.4124E-6,31.46205,193.81981,2.6526948,0
3762994905.66533,,1857,12.3849,12.3849,9999.9052734375,9.89999989542412E-6,12.525147,0.25234982,26.288657,0.07948,27.270941,0.03817,53.559599,0.07948,1.0551741,13.571034,0.023738591,99.302604,0,0,1,,,,3.9533E-6,27.14812,156.8793,2.0988702,0
3762996051.27601,,1857,9.99322,9.99322,9999.857421875,9.89999989542412E-6,10.117945,0.21589014,12.894934,0.07247,16.589634,0.02221,29.484568,0.06898,0.33460989,9.4782462,0,100,0,0,1,,,,3.1108E-6,22.88133,102.37281,1.2744618,0
3762997064.2902,,1857,8.99199,8.99199,9999.833984375,9.89999989542412E-6,9.0971909,0.18270905,9.4277759,0.04628,12.847551,0.02544,22.275327,0.04628,0.80940375,8.3149594,0.0089760627,99.559024,0,0,1,,,,2.6811E-6,16.94065,82.758883,1.0363392,0
3762997924.05958,,1857,8.07376,8.07376,9999.9404296875,9.89999989542412E-6,8.1665124,0.1635381,7.1969033,0.04171,9.8006866,0.02665,16.99759,0.04171,1.2674153,7.3314764,0.006211126,99.653753,0,0,1,,,,2.3199E-6,14.77896,66.691925,0.88127011,0
3762999276.5653,,1857,6.508,6.508,9999.9404296875,9.89999989542412E-6,6.5836651,0.13350207,5.4863412,0.02559,5.5808247,0.01428,11.067166,0.02559,0.59340148,6.4578103,0.0082386521,99.490975,0,0,1,,,,1.7159E-6,13.36537,43.344646,0.83332629,0
3763000062.97934,,1857,5.84805,5.84805,9999.8935546875,9.89999989542412E-6,5.9156912,0.11992492,5.4345701,0.02036,4.1537121,0.01069,9.5882822,0.02036,0.76458691,6.4220132,0.005886771,99.627172,0,0,1,,,,1.4948E-6,13.06075,34.995403,0.91867035,0
3763000838.77515,,1857,5.25366,5.25366,9999.880859375,9.89999989542412E-6,5.3141669,0.10725704,5.8332935,0.0177,3.0705235,0.007884,8.903817,0.0177,0.75769083,6.832518,0.0043919803,99.715598,0,0,1,,,,1.3047E-6,13.76678,28.24037,1.0976873,0
3763002140.94383,,1857,4.23585,4.23585,9999.833984375,9.89999989542412E-6,4.2793586,0.077575932,7.5041911,0.02656,1.6206153,0.003687,9.1248064,0.02656,0.65225842,9.613699,0.0067435388,99.518935,0,0,1,,,,9.5225E-7,15.57255,18.31291,1.7535785,0
3763002995.46524,,1857,3.80738,3.80738,9999.857421875,9.89999989542412E-6,3.8532526,0.079674979,8.8274571,0.02471,1.1858551,0.003419,10.013312,0.02471,0.99439026,11.745743,0.0033084169,99.729803,0,0,1,,,,8.543E-7,24.07734,14.847556,2.2909106,0
3763003681.16047,,1857,3.41992,3.41992,9999.822265625,9.89999989542412E-6,3.4599533,0.070481262,10.403416,0.02574,0.85874114,0.004765,11.262157,0.02574,1.2687293,15.044741,0.0025476495,99.759176,0,0,1,,,,7.5012E-7,30.03599,11.971277,3.0068082,0
3763004577.99177,,1857,2.75948,2.75948,9999.9052734375,9.89999989542412E-6,2.7891595,0.047156881,14.603208,0.03216,0.43483855,0.002269,15.038046,0.03216,1.6303001,26.091024,0.0016793272,99.770313,0,0,1,,,,5.7762E-7,39.49462,7.7794105,5.235702,0
3763005555.25228,,1857,2.4789,2.4789,9999.833984375,9.89999989542412E-6,2.5108601,0.051071634,17.152601,0.02423,0.31831039,0.001483,17.470911,0.02423,0.17968898,34.282181,0.0013211798,99.784119,0,0,1,,,,5.1068E-7,68.77066,6.3044182,6.8313648,0
3763006985.08673,,1857,2.22668,2.22668,9999.9404296875,9.89999989542412E-6,2.2555875,0.045739644,20.273983,0.03409,0.22957329,0.001439,20.503557,0.03409,0.72539099,45.369982,0.0010263724,99.795268,0,0,1,,,,4.5283E-7,91.13352,5.087675,8.9883383,0
3763019604.78794,,1857,1.79654,1.79654,9999.845703125,9.89999989542412E-6,1.8237295,0.037784888,26.797578,0.03483,0.12533537,0.0008803,26.922913,0.03483,0.22800828,77.096006,0.0010308131,99.710627,0,0,1,,,,3.5022E-7,153.7758,3.3259891,14.693834,0
3763023192.26373,,1857,1.44956,1.44956,9999.9287109375,9.89999989542412E-6,1.4687624,0.029290051,35.304738,0.02928,0.072230485,0.0004048,35.376968,0.02928,0.32499651,127.46635,0.00056364775,99.782511,0,0,1,,,,2.7814E-7,200.9234,2.157263,24.037065,0
3763027586.65081,,1857,1.30212,1.30212,9999.9052734375,9.89999989542412E-6,1.3206083,0.027613199,39.341134,0.02994,0.056484766,0.0002353,39.397619,0.02994,0.048556684,159.04412,0.00055106813,99.757396,0,0,1,,,,2.4832E-7,317.2706,1.7440063,29.790161,0
3763033454.81862,,1857,1.16965,1.16965,9999.98828125,9.89999989542412E-6,1.1861957,0.024979683,43.371553,0.04308,0.044890927,0.0003298,43.416444,0.04308,0.78270664,195.81649,0.00045466479,99.774699,0,0,1,,,,2.2222E-7,395.8445,1.4070602,36.563573,0
3763041688.77012,,1857,0.943627,0.943627,10000.0361328125,9.89999989542412E-6,0.95892256,0.021589576,49.813595,0.03752,0.02953736,0.0002339,49.843132,0.03752,0.037633912,284.70376,0.00048072069,99.714089,0,0,1,,,,1.7557E-7,478.2312,0.91953247,51.947463,0
3763051074.34639,,1857,0.847675,0.847675,10000.0244140625,9.89999989542412E-6,0.86142437,0.018805346,51.477684,0.04505,0.024432631,0.0002813,51.502116,0.04505,0.064609942,331.64864,0.0004470069,99.714941,0,0,1,,,,1.5573E-7,665.15,0.74205195,59.758797,0
3763062306.88933,,1857,0.761446,0.761446,10000.0009765625,9.89999989542412E-6,0.7747363,0.016801812,52.942944,0.04524,0.020480989,0.0003097,52.963425,0.04524,0.038566424,380.94766,0.00048227455,99.671414,0,0,1,,,,1.3949E-7,760.9786,0.60021634,68.336728,0
3763077346.9216,,1857,0.61444,0.61444,10000.0244140625,9.89999989542412E-6,0.71283161,0.0091756526,53.430761,0.3361,0.018121112,0.000205,53.448882,0.3361,0.29242698,232.3352,0,100,0,0,1,,,,2.3005E-7,548.6278,0.5081289,74.955656,0
3763123795.6325,,1857,49.9494,49.9494,14999.845703125,9.89999989542412E-6,50.469962,0.97864135,611.38018,3.37,425.90623,0.4071,1037.2864,3.345,0.19550177,78.98253,0,100,0,0,1,,,,1.3133E-5,151.2766,2547.217,12.113744,0
3763135761.94463,,1857,44.8782,44.8782,14999.90625,9.89999989542412E-6,45.364104,0.90941601,517.76223,1.688,346.24342,0.2878,864.00565,1.688,0.17481816,73.297293,0.23802939,98.652787,0,0,1,,,,1.1846E-5,137.8211,2057.9019,11.413479,0
3763154442.79905,,1857,36.1115,36.1115,14999.8935546875,9.89999989542412E-6,36.552517,0.79191668,367.86173,0.69,231.69346,0.186,599.55519,0.69,2.6092993,57.109596,0.12044285,99.112457,0,0,1,,,,1.0534E-5,129.4121,1336.0865,10.063923,0
3763162688.28831,,1857,32.5988,32.5988,14999.9892578125,9.89999989542412E-6,32.932848,0.68243627,307.23335,2.377,192.29481,0.1657,499.52817,2.377,0.074135856,56.399119,0.29863285,97.775346,0,0,1,,,,8.9337E-6,103.9531,1084.5725,9.3290854,0
3763168474.12304,,1857,29.3183,29.3183,14999.9287109375,9.89999989542412E-6,29.686122,0.6276941,248.14873,0.4774,159.09149,0.1498,407.24022,0.4774,0.18646136,44.171127,0.029566439,99.719011,0,0,1,,,,9.2293E-6,99.26086,881.26586,8.3590821,0
3763175139.43711,,1857,23.5403,23.5403,15000.060546875,9.89999989542412E-6,23.832081,0.5238424,159.53978,0.2929,104.87896,0.09221,264.41874,0.2929,5.2046186,34.69449,0.047440157,99.429517,0,0,1,,,,7.6373E-6,80.22599,567.96808,6.6943284,0
3763177900.63886,,1857,21.1775,21.1775,14999.9892578125,9.89999989542412E-6,21.414567,0.43032776,123.95756,0.2985,85.127093,0.07678,209.08465,0.2985,0.56965083,30.820184,0.074016572,99.007962,0,0,1,,,,6.808E-6,58.96207,458.58369,5.7884692,0
3763180047.86325,,1857,19.0231,19.0231,15000.01171875,9.89999989542412E-6,19.24293,0.3789865,94.726663,0.1907,69.027349,0.08734,163.75401,0.1907,1.1735232,25.779396,0.03395257,99.460839,0,0,1,,,,6.3637E-6,50.21011,370.29037,4.9226735,0
3763182267.61844,,1857,15.2955,15.2955,15000.0009765625,9.89999989542412E-6,15.476473,0.33519774,52.03858,0.1422,43.616143,0.05908,95.654724,0.1422,3.4923295,18.99466,0.020747886,99.560454,0,0,1,,,,5.0425E-6,43.42021,239.52121,3.3624316,0
3763183291.59546,,1857,13.7734,13.7734,15000.0361328125,9.89999989542412E-6,13.921357,0.27738503,37.680437,0.1285,34.71373,0.04864,72.394167,0.1285,0.4910496,16.483736,0.047398347,98.853899,0,0,1,,,,4.4057E-6,31.79411,193.80418,2.706664,0
3763184183.72975,,1857,12.3852,12.3852,15000.060546875,9.89999989542412E-6,12.52401,0.25209497,27.156597,0.08613,27.268161,0.03817,54.424758,0.08613,1.3432332,13.8457,0.028619782,99.176583,0,0,1,,,,3.9389E-6,27.54061,156.85084,2.1683627,0
3763185324.71148,,1857,9.99338,9.99338,14999.9892578125,9.89999989542412E-6,10.117782,0.21358226,14.381697,0.08609,16.588337,0.02221,30.970034,0.08318,0.2842387,9.9331345,0,100,0,0,1,,,,3.1179E-6,23.62423,102.36951,1.4214279,0
3763186356.11459,,1857,8.99182,8.99182,14999.9892578125,9.89999989542412E-6,9.093982,0.17930797,11.329056,0.1481,12.839899,0.02546,24.168955,0.1459,1.6667477,8.989332,0,100,0,0,1,,,,2.6886E-6,18.34967,82.700509,1.2457751,0
3763187239.39625,,1857,8.07367,8.07367,14999.9892578125,9.89999989542412E-6,8.1655599,0.1638586,9.4590449,0.05739,9.7976095,0.02664,19.256654,0.05739,1.0557197,8.3258624,0.0078527724,99.623347,0,0,1,,,,2.315E-6,16.74369,66.676369,1.1584074,0
3763188627.38704,,1857,6.50846,6.50846,15000.0478515625,9.89999989542412E-6,6.5787814,0.12813886,8.7762113,0.05967,5.5726916,0.01426,14.348903,0.05967,2.0001374,8.5005003,0.017637775,99.128392,0,0,1,,,,1.6936E-6,16.14552,43.280365,1.3340178,0
3763189464.06374,,1857,5.84892,5.84892,14999.953125,9.89999989542412E-6,5.9163632,0.12099702,9.4637665,0.04394,4.1557338,0.0107,13.6195,0.04394,3.9242828,9.1235388,0.0052817262,99.726987,0,0,1,,,,1.4948E-6,18.75618,35.003354,1.5995919,0
3763190319.29256,,1857,5.25396,5.25396,15000.0478515625,9.89999989542412E-6,5.3145639,0.10777753,10.636576,0.02448,3.07133,0.007886,13.707906,0.02448,0.7080509,10.561649,0.0053915499,99.706196,0,0,1,,,,1.3002E-6,21.26959,28.24459,2.0014015,0
3763191743.50849,,1857,4.23722,4.23722,15000.0947265625,9.89999989542412E-6,4.2805139,0.075142293,14.268832,0.04571,1.6219086,0.003693,15.890741,0.04571,0.36262879,16.789612,0.006037629,99.606677,0,0,1,,,,9.4948E-7,25.75069,18.322799,3.3334391,0
3763192806.75181,,1857,3.80762,3.80762,15000.0009765625,9.89999989542412E-6,3.8543366,0.079667135,16.742315,0.05115,1.1868394,0.003414,17.929154,0.05115,1.0369867,20.944406,0.0045227979,99.649744,0,0,1,,,,8.5866E-7,42.99434,14.855911,4.3437604,0
3763193753.44404,,1857,3.4199,3.4199,15000.0009765625,9.89999989542412E-6,3.4623577,0.070383165,19.578221,0.04304,0.86064879,0.004769,20.43887,0.04304,0.59638929,27.199166,0.0030549494,99.720889,0,0,1,,,,7.5338E-7,54.2717,11.987921,5.6545923,0
3763195113.09804,,1857,2.75929,2.75929,15000.01171875,9.89999989542412E-6,2.7947603,0.047479909,26.557959,0.04756,0.43743745,0.002282,26.995396,0.04756,0.40428777,46.232129,0.0014019715,99.809437,0,0,1,,,,5.8499E-7,70.8835,7.8106852,9.5027679,0
3763196824.33537,,1857,2.47866,2.47866,14999.9775390625,9.89999989542412E-6,2.5173235,0.050185172,30.338829,0.03876,0.32075891,0.001498,30.659588,0.03876,1.4275451,59.308805,0.002053957,99.664396,0,0,1,,,,5.1865E-7,117.0279,6.3369178,12.052018,0
3763199069.57185,,1857,2.22637,2.22637,14999.953125,9.89999989542412E-6,2.267429,0.044769571,34.47081,0.05691,0.23330016,0.001423,34.70411,0.05691,0.17103305,74.817811,0.001243941,99.750399,0,0,1,,,,4.6499E-7,148.2785,5.1412344,15.202597,0
3763202646.68423,,1857,1.79655,1.79655,14999.9892578125,9.89999989542412E-6,1.8446876,0.03557555,41.808596,0.06633,0.12930118,0.0009324,41.937897,0.06633,0.52917869,116.89405,0.001224991,99.657898,0,0,1,,,,3.5999E-7,185.8339,3.4028724,22.664323,0
3763206454.66637,,1857,1.61367,1.61367,15000.1318359375,9.89999989542412E-6,1.6767405,0.031469432,45.794235,0.06469,0.10037984,0.000621,45.894615,0.06469,0.21397901,130.71343,0,100,0,0,1,,,,3.5111E-7,264.8264,2.8114586,27.311463,0
3763211721.35094,,1857,1.44957,1.44957,15000.0244140625,9.89999989542412E-6,1.4697559,0.030905872,49.657927,0.04008,0.072285231,0.0004053,49.730212,0.04008,0.088170998,178.82807,0.00066099504,99.744689,0,0,1,,,,2.788E-7,362.6112,2.1601824,33.786513,0
3763218916.30361,,1857,1.16968,1.16968,14999.9775390625,9.89999989542412E-6,1.1885985,0.027028743,53.231072,0.04303,0.045121958,0.0003256,53.276194,0.04303,0.017371425,240.28926,0.00043185495,99.787167,0,0,1,,,,2.2219E-7,423.6235,1.4127664,44.784737,0
3763227118.29453,,1857,1.05063,1.05063,14999.9892578125,9.89999989542412E-6,1.0665768,0.022993803,53.398218,0.03736,0.036202092,0.0003544,53.43442,0.03736,0.053602921,274.84516,0.00047178464,99.745821,0,0,1,,,,1.9491E-7,547.9112,1.1375861,50.065046,0
3763236286.66352,,1857,0.943674,0.943674,14999.8818359375,9.89999989542412E-6,0.95868771,0.021016808,52.025322,0.03797,0.029501484,0.0002338,52.054824,0.03797,0.098541792,303.75048,0.00049991312,99.708589,0,0,1,,,,1.7187E-7,606.1735,0.91908212,54.267226,0
3763247863.7561,,1857,0.761466,0.761466,14999.8935546875,9.89999989542412E-6,0.77616553,0.020326449,46.724049,0.0487,0.020560726,0.000311,46.74461,0.0487,5.0792701,352.04592,0.00070808462,99.540414,0,0,1,,,,1.3339E-7,655.5569,0.60243293,60.198563,0
3763258677.32619,,1857,0.684045,0.684045,15000.0361328125,9.89999989542412E-6,0.6979775,0.01616329,42.976145,0.04779,0.017638646,0.0001782,42.993783,0.04779,0.15703572,358.62997,0.00056035379,99.617531,0,0,1,,,,1.2034E-7,738.0862,0.48717258,61.572393,0
3763272330.07491,,1857,0.614413,0.614413,15000.0009765625,9.89999989542412E-6,0.62670543,0.014440478,39.570963,0.04948,0.015325391,0.000173,39.586289,0.04948,3.4982952,374.61247,0.00080939584,99.438536,0,0,1,,,,1.0627E-7,745.2157,0.3927597,63.141248,0
3763294026.50837,,1857,45.0931,45.0931,20000.15625,9.89999989542412E-6,45.663486,0.92113642,511.11718,1.565,350.48782,0.2925,861.605,1.538,14.2265,67.248442,0,100,0,0,1,,,,1.2812E-5,156.181,2085.1539,11.193127,0
3763305755.90478,,1857,40.3438,40.3438,20000.23828125,9.89999989542412E-6,40.773128,0.82965816,439.26753,2.332,283.12202,0.233,722.38955,2.332,0.10613445,68.184363,0.29404194,98.198777,0,0,1,,,,1.0667E-5,126.1629,1662.4479,10.773457,0
3763315294.9275,,1857,36.3446,36.3446,20000.15625,9.89999989542412E-6,36.789023,0.77510519,367.90414,1.056,234.41561,0.1885,602.31975,1.056,0.067676395,57.174055,0.094075419,99.309038,0,0,1,,,,1.0562E-5,124.1603,1353.4322,10.000378,0
3763327842.47332,,1857,29.1337,29.1337,20000.130859375,9.89999989542412E-6,29.473697,0.6296852,249.81193,0.5962,157.03414,0.1476,406.84607,0.5962,9.4510406,45.874596,0.11636018,98.932521,0,0,1,,,,8.9048E-6,98.96391,868.69881,8.4757584,0
3763332595.35244,,1857,26.2213,26.2213,20000.060546875,9.89999989542412E-6,26.530538,0.51634985,200.40964,0.4765,128.87896,0.1123,329.2886,0.463,0.10115995,38.153058,0,100,0,0,1,,,,8.6307E-6,76.94046,703.86947,7.553923,0
3763335707.8309,,1857,23.6206,23.6206,20000.16796875,9.89999989542412E-6,23.90214,0.49745296,159.66455,0.3454,105.50782,0.09274,265.17236,0.3454,0.39084975,34.972376,0.062507366,99.255462,0,0,1,,,,7.603E-6,72.5201,571.3123,6.6799268,0
3763339488.63886,,1857,19.0914,19.0914,20000.19140625,9.89999989542412E-6,19.326574,0.40588347,95.35839,0.4212,69.616055,0.08682,164.97445,0.4121,3.2756229,25.378229,0,100,0,0,1,,,,6.5006E-6,60.9164,373.51646,4.9340556,0
3763341454.38622,,1857,17.1123,17.1123,20000.203125,9.89999989542412E-6,17.30776,0.33835551,71.239931,0.2693,55.476104,0.08029,126.71603,0.257,0.3377937,21.676854,0,100,0,0,1,,,,5.8457E-6,44.79451,299.55854,4.1160689,0
3763342590.91601,,1857,15.3618,15.3618,20000.19140625,9.89999989542412E-6,15.531545,0.32147346,53.13455,0.2021,43.969204,0.05953,97.103754,0.2021,0.36896191,19.700793,0.0521285,98.936608,0,0,1,,,,4.9448E-6,40.20073,241.2289,3.421073,0
3763344032.13587,,1857,12.3676,12.3676,20000.203125,9.89999989542412E-6,12.517924,0.26732797,28.398019,0.1343,27.232241,0.03813,55.63026,0.1288,0.64929272,13.821752,0,100,0,0,1,,,,4.0248E-6,32.98804,156.69841,2.2685886,0
3763344865.1046,,1857,11.1188,11.1188,20000.21484375,9.89999989542412E-6,11.243058,0.22350491,21.126093,0.06197,21.269336,0.03176,42.395429,0.06197,1.9844771,12.206575,0.011323657,99.629619,0,0,1,,,,3.4764E-6,23.93714,126.40636,1.8790344,0
3763345606.89593,,1857,9.99374,9.99374,20000.21484375,9.89999989542412E-6,10.106898,0.20250803,16.533584,0.05423,16.546018,0.02215,33.079602,0.05423,3.5033906,10.854082,0.0088332021,99.675003,0,0,1,,,,3.0501E-6,21.61783,102.14939,1.6358712,0
3763347215.29508,,1857,8.0719,8.0719,20000.2265625,9.89999989542412E-6,8.1592067,0.16122341,12.507296,0.1316,9.7822216,0.0266,22.289517,0.1289,1.0908937,9.7924047,0,100,0,0,1,,,,2.2762E-6,19.77169,66.572654,1.5329059,0
3763348109.96358,,1857,7.25111,7.25111,20000.19140625,9.89999989542412E-6,7.3336673,0.14900286,12.299522,0.06149,7.4007445,0.0185,19.700266,0.06149,3.5964352,9.9174963,0.010149331,99.564086,0,0,1,,,,1.9898E-6,20.20724,53.782676,1.6771311,0
3763349004.80548,,1857,6.5122,6.5122,20000.23828125,9.89999989542412E-6,6.5855814,0.13232102,13.033981,0.04961,5.5857616,0.01429,18.619743,0.04961,1.5402091,10.779435,0.0095293019,99.57906,0,0,1,,,,1.7309E-6,21.66791,43.369883,1.9791694,0
3763350456.35544,,1857,5.25207,5.25207,20000.203125,9.89999989542412E-6,5.3027892,0.094542127,16.575672,0.06784,3.0529455,0.007842,19.628617,0.06784,0.77372058,15.62277,0.0099278234,99.515171,0,0,1,,,,1.2608E-6,24.90162,28.119573,3.1258402,0
3763351485.03758,,1857,4.71913,4.71913,20000.21484375,9.89999989542412E-6,4.7752923,0.098666982,19.092201,0.03452,2.2498942,0.006061,21.342095,0.03452,1.0222607,18.920953,0.0056426246,99.683172,0,0,1,,,,1.1308E-6,38.93858,22.803416,3.998122,0
3763352647.49253,,1857,4.23863,4.23863,20000.251953125,9.89999989542412E-6,4.2903572,0.087451575,22.004114,0.03239,1.6324759,0.00374,23.63659,0.03239,0.21165703,24.018029,0.0036716705,99.76182,0,0,1,,,,9.8616E-7,48.24248,18.407165,5.1287371,0
3763354344.01945,,1857,3.41998,3.41998,20000.1796875,9.89999989542412E-6,3.4580927,0.058946932,29.404069,0.05458,0.85751922,0.004763,30.261588,0.05458,1.2464845,40.022683,0.0017012507,99.845407,0,0,1,,,,7.5722E-7,62.01445,11.958405,8.5029731,0
3763355805.21602,,1857,3.07205,3.07205,20000.130859375,9.89999989542412E-6,3.1149986,0.062945787,33.257603,0.04,0.61141641,0.00326,33.869019,0.04,0.84131861,50.695537,0.0018126362,99.797915,0,0,1,,,,6.6939E-7,101.8177,9.7032161,10.676603,0
3763357741.05455,,1857,2.75952,2.75952,20000.251953125,9.89999989542412E-6,2.8027609,0.056105134,37.536144,0.03855,0.44103697,0.002301,37.977181,0.03855,0.316541,64.116885,0.0015650408,99.786913,0,0,1,,,,5.9355E-7,128.8236,7.8554685,13.39256,0
3763360487.49303,,1857,2.22655,2.22655,20000.203125,9.89999989542412E-6,2.2786294,0.039963425,45.655317,0.07116,0.23691677,0.001407,45.892234,0.07116,0.13663645,94.411278,0.00078231775,99.838401,0,0,1,,,,4.8687E-7,158.5301,5.1921519,20.036307,0
3763366702.9522,,1857,1.99998,1.99998,20000.072265625,9.89999989542412E-6,2.0982473,0.040344396,47.154043,0.156,0.18421278,0.001544,47.338255,0.156,0.080444699,106.00407,0.00095711813,99.766532,0,0,1,,,,4.4761E-7,213.5837,4.4026415,22.473063,0
3763370852.72283,,1857,1.79659,1.79659,20000.15625,9.89999989542412E-6,1.9129051,0.034259027,50.920416,0.1012,0.14227906,0.001121,51.062695,0.1012,0.30656753,121.03391,0.00089368615,99.733561,0,0,1,,,,4.2301E-7,236.5846,3.6592059,26.619416,0
3763377010.38565,,1857,1.4496,1.4496,20000.013671875,9.89999989542412E-6,1.4704813,0.032727842,53.716941,0.05055,0.072493499,0.0004073,53.789435,0.05055,0.022375626,192.88589,0.00057666118,99.777379,0,0,1,,,,2.7949E-7,292.8729,2.1623154,36.530175,0
3763383392.05786,,1857,1.30206,1.30206,19999.91796875,9.89999989542412E-6,1.3205268,0.027997483,52.858168,0.03681,0.056480718,0.0002353,52.914649,0.03681,0.041843131,215.05391,0.00055394407,99.757838,0,0,1,,,,2.4665E-7,429.8929,1.7437911,40.028091,0
3763391040.08147,,1857,1.16964,1.16964,20000.109375,9.89999989542412E-6,1.1865126,0.025438874,51.178611,0.04177,0.044920215,0.0003292,51.223531,0.04177,0.13297876,234.82083,0.00045110918,99.780262,0,0,1,,,,2.1862E-7,472.1409,1.4078121,43.133644,0
3763399783.23847,,1857,0.943701,0.943701,20000.109375,9.89999989542412E-6,0.96018997,0.024347951,44.780342,0.04442,0.029611509,0.0002343,44.809954,0.04442,0.51496343,266.04662,0.0005783493,99.669732,0,0,1,,,,1.6899E-7,504.6443,0.92196479,46.636961,0
3763408553.0687,,1857,0.847781,0.847781,20000.15625,9.89999989542412E-6,0.86196935,0.019779686,40.622247,0.05612,0.024464263,0.0002807,40.646712,0.05612,1.7993505,273.82628,0.000482657,99.706104,0,0,1,,,,1.4888E-7,547.4782,0.74299116,47.127253,0
3763417285.12988,,1857,0.761491,0.761491,20000.0234375,9.89999989542412E-6,0.77506316,0.017904458,36.361638,0.03737,0.020499418,0.00031,36.382137,0.03737,0.59428086,277.5425,0.00068507654,99.559736,0,0,1,,,,1.3167E-7,552.4951,0.6007229,46.91442,0
3763429384.61453,,1857,0.614396,0.614396,20000.19140625,9.89999989542412E-6,0.62692338,0.014756285,29.335196,0.0421,0.015335486,0.0001727,29.350531,0.0421,0.87596925,292.03379,0.001232797,99.185013,0,0,1,,,,1.0133E-7,555.1081,0.39303292,46.792314,0